在 Rust 1.80.1 中，`panic!` 宏是用于处理不可恢复错误的机制。它会立即中断程序执行，并显示错误信息。Rust 提供了两种方式来处理 `panic!` 引发的崩溃：**栈展开（unwinding）**和**终止（abort）**。在栈展开模式下，`panic!` 会回滚当前的调用栈，逐步调用每个变量的析构函数，以保证资源被正确释放。

### 1. `panic!` 宏的用法
`panic!` 宏可以手动调用，当程序遇到不可恢复的错误时通过 `panic!` 结束。例如：
```rust
fn main() {
    panic!("A critical error occurred!");
}
```
此时，程序会崩溃并显示错误信息 `A critical error occurred!`，伴随着栈回溯信息，帮助开发者定位问题。

### 2. 栈展开与析构函数调用
Rust 默认采用 **栈展开（unwinding）** 机制，当 `panic!` 触发时，Rust 会回溯调用栈，逐步释放所有被分配的资源。具体来说，它会：
- **调用每个变量的析构函数**：栈展开的过程中，Rust 会确保每个变量的析构函数（`Drop` trait）被依次调用，确保资源（如内存、文件句柄等）被正确释放。

例如：
```rust
struct Resource;

impl Drop for Resource {
    fn drop(&mut self) {
        println!("Resource is being dropped");
    }
}

fn main() {
    let _res = Resource;
    panic!("Error occurred!"); // 引发 panic，Resource 会被释放
}
```
在上面的例子中，当 `panic!` 触发时，Rust 会在展开栈时调用 `Resource` 的 `drop` 方法，确保资源被清理。

### 3. 栈展开与终止策略
Rust 默认使用栈展开（unwind）来处理 panic，但在某些性能敏感场景（如嵌入式系统）中，可以选择终止（abort）策略，以避免栈展开带来的额外开销。在终止模式下，程序不会进行栈回溯，也不会调用变量的析构函数，而是直接中止。

可以在 `Cargo.toml` 中配置 panic 策略：
```toml
[profile.release]
panic = 'abort'
```
此设置表示在发布模式下，Rust 会直接终止程序，而不进行栈展开。

### 4. 错误传播与 panic
虽然 `panic!` 主要用于不可恢复的错误，但 Rust 提倡通过 `Result` 和 `Option` 类型进行错误传播，避免直接使用 `panic!`。`Result` 枚举用于表示操作的成功（`Ok`）或失败（`Err`），而不是通过 `panic!` 崩溃整个程序。

示例：
```rust
fn divide(a: i32, b: i32) -> Result<i32, String> {
    if b == 0 {
        return Err(String::from("Division by zero"));
    }
    Ok(a / b)
}

fn main() {
    match divide(10, 0) {
        Ok(result) => println!("Result: {}", result),
        Err(e) => println!("Error: {}", e),
    }
}
```
这种方式允许开发者在遇到错误时进行适当处理，而不是直接让程序崩溃。

### 5. 捕获 `panic!`
Rust 还提供了捕获 panic 的机制，通过 `std::panic::catch_unwind`，可以捕获 `panic!` 并继续执行其他代码。这种机制主要用于隔离某些可能会 panic 的代码块，使得 panic 不会影响整个程序。

```rust
use std::panic;

fn main() {
    let result = panic::catch_unwind(|| {
        println!("About to panic");
        panic!("This is a panic");
    });

    match result {
        Ok(_) => println!("No panic occurred"),
        Err(_) => println!("Panic was caught"),
    }
}
```
```rust
use std::panic;

fn main() {
    let result = panic::catch_unwind(|| {
        println!("no panic");
        1001
    });

    match result {
        Ok(a) => println!("No panic occurred {a}"),
        Err(_) => println!("Panic was caught"),
    }
}
```
在这个例子中，`catch_unwind` 捕获了 panic，程序不会崩溃，而是继续执行。

### 6. Panic 与测试
在测试代码中，`panic!` 也被用作验证某些操作是否正确处理错误。例如，使用 `#[should_panic]` 属性，测试函数会验证是否触发了 panic。

```rust
#[test]
#[should_panic(expected = "assertion failed")]
fn test_panic() {
    assert!(false, "assertion failed");
}
```

### 7. 总结
- **栈展开与析构函数**：Rust 在 panic 期间会展开栈，并调用每个变量的析构函数以确保资源的释放。
- **终止策略**：可以通过配置选择直接终止程序，而不展开栈。
- **错误传播**：Rust 提倡使用 `Result` 和 `Option` 进行错误处理，避免过多使用 `panic!`。
- **捕获 panic**：使用 `catch_unwind` 机制可以捕获 panic，并控制程序的崩溃行为。

---

这个版本更加详细地解释了 `panic!` 的工作机制、栈展开与析构函数调用的过程，以及错误传播的相关内容。如果你还有其他问题，欢迎继续讨论！
